Workbook

Sheet Summary
A1: IDEA Brand Coach Gen 3 — Execution & Time Tracker
A2: Generated 2026-05-25 · execution + effort view at strategic-objective grain · links to feature_status_tracker.xlsx by feature ID
A4: Time invested by source
A5: Source | B5: Hours | C5: Share
A6: Logged (Clockify) | B6: 9.78 | C6: 0.52770733
A7: Meetings (Fathom, unlogged) | B7: 2.7 | C7: 0.14568607
A8: Estimated (agent sessions) | B8: 6.05 | C8: 0.32660659
A9: GRAND TOTAL | B9: 18.53
A10: Per-objective rollup
A11: Objective | B11: Status | C11: Rollup % | D11: Total Hours
A12: =Objectives!B2 | B12: =Objectives!F2 | C12: =Objectives!G2 | D12: =Objectives!K2
A13: =Objectives!B3 | B13: =Objectives!F3 | C13: =Objectives!G3 | D13: =Objectives!K3
A14: =Objectives!B4 | B14: =Objectives!F4 | C14: =Objectives!G4 | D14: =Objectives!K4
A15: =Objectives!B5 | B15: =Objectives!F5 | C15: =Objectives!G5 | D15: =Objectives!K5
A16: =Objectives!B6 | B16: =Objectives!F6 | C16: =Objectives!G6 | D16: =Objectives!K6
A17: =Objectives!B7 | B17: =Objectives!F7 | C17: =Objectives!G7 | D17: =Objectives!K7
A18: =Objectives!B8 | B18: =Objectives!F8 | C18: =Objectives!G8 | D18: =Objectives!K8

Sheet Time Log
A1: Date | B1: Source | C1: Objective | D1: Description | E1: Hours | F1: Note
A2: 46086 | B2: meeting | C2: O7 | D2: Meeting: Impromptu Google Meet — pivot to conversational AI coach | E2: 0.6 | F2: Unlogged. Pivot decision + $500 acceleration. Est. from max summary ts ~2188s.
A3: 46086 | B3: meeting | C3: O7 | D3: Meeting: Impromptu Zoom — refine value prop & IDEA workflow | E3: 0.7 | F3: Unlogged. IDEA framework workflow, chat-first canvas. Est. from max summary ts ~2336s.
A4: 46099 | B4: meeting | C4: O7 | D4: Meeting: IDEA Brand Coach Sync Up | E4: 1.4 | F4: Unlogged. Skill-based model pivot, beta plan, cost analysis. Est. from max summary ts ~4939s.
A5: 46118 | B5: logged | C5: O7 | D5: push to Lovable | E5: 0.03
A6: 46118 | B6: logged | C6: O1 | D6: Integrate Claude agent SDK | E6: 0.17
A7: 46119 | B7: logged | C7: O3 | D7: optimize extraction fields + field review flow | E7: 0.14
A8: 46119 | B8: logged | C8: O3 | D8: optimize extraction fields + field review flow | E8: 0.25
A9: 46119 | B9: logged | C9: O1 | D9: clean up broken text entry in chat, hardcoded text always appearing for suggested edits, push updated working app to Lovable & verify doc gen works | E9: 0.76
A10: 46131 | B10: logged | C10: O7 | D10: create marketing video in remotion | E10: 0.03
A11: 46131 | B11: logged | C11: O7 | D11: create marketing video in remotion | E11: 0.24
A12: 46131 | B12: logged | C12: O7 | D12: create marketing video in remotion | E12: 0.08
A13: 46135 | B13: logged | C13: O7 | D13: review Trevor's docs & meet with him to discuss next steps | E13: 2.19
A14: 46136 | B14: estimated | C14: O7 | D14: Agent session 53d8367d (-Users-matthewkerns-workspace-ecommerce-ecommerce-tools-brand-systems-idea-brand-coach, 52 events) | E14: 0.633 | F14: estimated from JSONL active time (15-min idle cap)
A15: 46136 | B15: estimated | C15: O7 | D15: Agent session a754fbda (-Users-matthewkerns-workspace-ecommerce-ecommerce-tools-brand-systems-idea-brand-coach, 41 events) | E15: 0.34 | F15: estimated from JSONL active time (15-min idle cap)
A16: 46136 | B16: logged | C16: O7 | D16: investigate obsidian and autoresearch | E16: 0.2
A17: 46136 | B17: logged | C17: O7 | D17: investigate obsidian and autoresearch | E17: 0.25
A18: 46140 | B18: logged | C18: O7 | D18: use the app for InfinityVault branding funnel spreadsheet build out | E18: 0.03
A19: 46141 | B19: logged | C19: O7 | D19: brand funnel capture | E19: 0.21
A20: 46145 | B20: logged | C20: O7 | D20: Message Trevor | E20: 0.3
A21: 46145 | B21: logged | C21: O7 | D21: map out ideal case study | E21: 0.14
A22: 46145 | B22: logged | C22: O7 | D22: map out ideal case study | E22: 0.39
A23: 46147 | B23: logged | C23: O7 | D23: Reply to Trevor, review his mock ups | E23: 0.13
A24: 46148 | B24: logged | C24: O7 | D24: Meet with Trevor | E24: 1.35
A25: 46148 | B25: logged | C25: O7 | D25: Make skill that manages brand workspace sheet | E25: 0.17 | F25: review: unmatched -> default O7
A26: 46155 | B26: estimated | C26: O7 | D26: Agent session 752b7d11 (-Users-matthewkerns-workspace-ecommerce-ecommerce-tools-brand-systems-idea-brand-coach, 438 events) | E26: 1.355 | F26: estimated from JSONL active time (15-min idle cap)
A27: 46155 | B27: logged | C27: O7 | D27: Review workbook, request dev agent progress report towards this planned outcome | E27: 0.01
A28: 46155 | B28: logged | C28: O7 | D28: Review workbook, request dev agent progress report towards this planned outcome | E28: 0.03
A29: 46155 | B29: logged | C29: O7 | D29: Review workbook, request dev agent progress report towards this planned outcome | E29: 0.22
A30: 46155 | B30: logged | C30: O7 | D30: Skim workbook with plan | E30: 0.05
A31: 46155 | B31: logged | C31: O7 | D31: build out spreadsheet with alpha beta and GA launch plan | E31: 0.24
A32: 46155 | B32: logged | C32: O7 | D32: Plan bare minimum beta readiness in a new thread with all available and relevant context - including my PRD | E32: 0.01
A33: 46156 | B33: estimated | C33: O7 | D33: Agent session e50443e0 (-Users-matthewkerns-workspace-ecommerce-ecommerce-tools-brand-systems-idea-brand-coach, 77 events) | E33: 0.647 | F33: estimated from JSONL active time (15-min idle cap)
A34: 46158 | B34: logged | C34: O7 | D34: send follow up about brand coach feedback loop | E34: 0.13
A35: 46158 | B35: logged | C35: O7 | D35: review updated workbook | E35: 0.23
A36: 46158 | B36: logged | C36: O7 | D36: integrate top problems we're solving for the user into the workbook | E36: 0.15
A37: 46158 | B37: logged | C37: O7 | D37: message Trevor, update feature workbook, send him Launch Roadmap + Feature workbook | E37: 0.43
A38: 46158 | B38: logged | C38: O7 | D38: write out todos | E38: 0.22
A39: 46158 | B39: logged | C39: O7 | D39: review spreadsheet and plan reply to Trevor | E39: 0.3
A40: 46159 | B40: logged | C40: O7 | D40: Run Trevor‘s document through my Claude thread for the marketing plan for the quarter | E40: 0.46
...

Sheet Objectives
A1: ID | B1: Objective | C1: Linked Features | D1: Description | E1: Phase | F1: Status | G1: Rollup % | H1: Hours Logged | I1: Hours Meeting | J1: Hours Estimated | K1: Hours Total
A2: O1 | B2: Diagnostic & Trust Gap™ | C2: F-001, F-002 | D2: Layer 1 conversation: 10-question diagnostic + sidebar population/follow-up | E2: Alpha | F2: in_progress | G2: 0.3 | H2: =SUMIFS('Time Log'!$E$2:$E$46,'Time Log'!$C$2:$C$46,$A2,'Time Log'!$B$2:$B$46,"logged") | I2: =SUMIFS('Time Log'!$E$2:$E$46,'Time Log'!$C$2:$C$46,$A2,'Time Log'!$B$2:$B$46,"meeting") | J2: =SUMIFS('Time Log'!$E$2:$E$46,'Time Log'!$C$2:$C$46,$A2,'Time Log'!$B$2:$B$46,"estimated") | K2: =SUM(H2:J2)
A3: O2 | B3: Draft Canvas Synthesis | C3: F-003 | D3: Synthesize Layer 1 answers into a draft brand canvas | E3: Alpha | F3: in_progress | G3: 0.42 | H3: =SUMIFS('Time Log'!$E$2:$E$46,'Time Log'!$C$2:$C$46,$A3,'Time Log'!$B$2:$B$46,"logged") | I3: =SUMIFS('Time Log'!$E$2:$E$46,'Time Log'!$C$2:$C$46,$A3,'Time Log'!$B$2:$B$46,"meeting") | J3: =SUMIFS('Time Log'!$E$2:$E$46,'Time Log'!$C$2:$C$46,$A3,'Time Log'!$B$2:$B$46,"estimated") | K3: =SUM(H3:J3)
A4: O3 | B4: Customer Insight Engine / Avatar Builder | C4: F-004, F-005, F-006 | D4: Avatar Builder sections 1-4, AI assistance, confidence scoring & edit lock | E4: Alpha/Beta | F4: in_progress | G4: 0.45 | H4: =SUMIFS('Time Log'!$E$2:$E$46,'Time Log'!$C$2:$C$46,$A4,'Time Log'!$B$2:$B$46,"logged") | I4: =SUMIFS('Time Log'!$E$2:$E$46,'Time Log'!$C$2:$C$46,$A4,'Time Log'!$B$2:$B$46,"meeting") | J4: =SUMIFS('Time Log'!$E$2:$E$46,'Time Log'!$C$2:$C$46,$A4,'Time Log'!$B$2:$B$46,"estimated") | K4: =SUM(H4:J4)
A5: O4 | B5: The Signature & Coach Mode v2 | C5: F-009 | D5: Stage 5 retention output: brand voice guide, Amazon listing copy | E5: Beta | F5: in_progress | G5: 0.45 | H5: =SUMIFS('Time Log'!$E$2:$E$46,'Time Log'!$C$2:$C$46,$A5,'Time Log'!$B$2:$B$46,"logged") | I5: =SUMIFS('Time Log'!$E$2:$E$46,'Time Log'!$C$2:$C$46,$A5,'Time Log'!$B$2:$B$46,"meeting") | J5: =SUMIFS('Time Log'!$E$2:$E$46,'Time Log'!$C$2:$C$46,$A5,'Time Log'!$B$2:$B$46,"estimated") | K5: =SUM(H5:J5)
A6: O5 | B6: Export & Deliverables | C6: F-007 | D6: PDF / Word / Markdown export of brand strategy | E6: Beta | F6: in_progress | G6: 0.72 | H6: =SUMIFS('Time Log'!$E$2:$E$46,'Time Log'!$C$2:$C$46,$A6,'Time Log'!$B$2:$B$46,"logged") | I6: =SUMIFS('Time Log'!$E$2:$E$46,'Time Log'!$C$2:$C$46,$A6,'Time Log'!$B$2:$B$46,"meeting") | J6: =SUMIFS('Time Log'!$E$2:$E$46,'Time Log'!$C$2:$C$46,$A6,'Time Log'!$B$2:$B$46,"estimated") | K6: =SUM(H6:J6)
A7: O6 | B7: Monetization / Pay Gate | C7: F-008 | D7: Stripe pay gate before premium outputs | E7: GA | F7: not_started | G7: 0 | H7: =SUMIFS('Time Log'!$E$2:$E$46,'Time Log'!$C$2:$C$46,$A7,'Time Log'!$B$2:$B$46,"logged") | I7: =SUMIFS('Time Log'!$E$2:$E$46,'Time Log'!$C$2:$C$46,$A7,'Time Log'!$B$2:$B$46,"meeting") | J7: =SUMIFS('Time Log'!$E$2:$E$46,'Time Log'!$C$2:$C$46,$A7,'Time Log'!$B$2:$B$46,"estimated") | K7: =SUM(H7:J7)
A8: O7 | B8: Launch & Strategy | C8: — | D8: Alpha->Beta->GA gates, ideabrandcoach.com site, TikTok-conditional, Trevor sync, roadmap/context upkeep | E8: All | F8: in_progress | G8: n/a | H8: =SUMIFS('Time Log'!$E$2:$E$46,'Time Log'!$C$2:$C$46,$A8,'Time Log'!$B$2:$B$46,"logged") | I8: =SUMIFS('Time Log'!$E$2:$E$46,'Time Log'!$C$2:$C$46,$A8,'Time Log'!$B$2:$B$46,"meeting") | J8: =SUMIFS('Time Log'!$E$2:$E$46,'Time Log'!$C$2:$C$46,$A8,'Time Log'!$B$2:$B$46,"estimated") | K8: =SUM(H8:J8)
B9: TOTAL | H9: =SUM(H2:H8) | I9: =SUM(I2:I8) | J9: =SUM(J2:J8) | K9: =SUM(K2:K8)

Sheet Meetings
A1: Date | B1: Title | C1: Recording ID | D1: URL | E1: Duration (h) | F1: In Clockify? | G1: Objective
A2: 46148 | B2: Impromptu Zoom — Gen 3 mockup review | C2: 144128256 | D2: https://fathom.video/calls/664335828 | E2: 1.35 | F2: Y | G2: O7
A3: 46135 | B3: 4/23 IDEA Brand Coach Part 2 | C3: 140691318 | D3: https://fathom.video/calls/649154125 | E3: 1.1 | F3: Y | G3: O7
A4: 46135 | B4: 4/23 IDEA Brand Coach Part 1 | C4: 140678453 | D4: https://fathom.video/calls/649118151 | E4: 1 | F4: Y | G4: O7
A5: 46099 | B5: IDEA Brand Coach Sync Up | C5: 130896361 | D5: https://fathom.video/calls/605088052 | E5: 1.4 | F5: N | G5: O7
A6: 46086 | B6: Impromptu Google Meet — pivot to conversational AI coach | C6: 127607831 | D6: https://fathom.video/calls/590988739 | E6: 0.6 | F6: N | G6: O7
A7: 46086 | B7: Impromptu Zoom — refine value prop & IDEA workflow | C7: 127583497 | D7: https://fathom.video/calls/590934937 | E7: 0.7 | F7: N | G7: O7
B9: N = meeting time NOT in Clockify (added as 'meeting' hours). Y = already counted in Clockify (reference only).

Sheet Sessions
A1: Date | B1: Session ID | C1: Worktree | D1: Events | E1: Active (h, est.) | F1: Objective
A2: 46167 | B2: 47cf9ccc | C2: planning | D2: 155 | E2: 0.3 | F2: O7
A3: 46167 | B3: 6c99fece | C3: planning | D3: 384 | E3: 1.068 | F3: O7
A4: 46167 | B4: 9b9fb0d5 | C4: planning | D4: 223 | E4: 0.472 | F4: O7
A5: 46167 | B5: 29a9c876 | C5: tooling | D5: 404 | E5: 1.238 | F5: O7
A6: 46156 | B6: e50443e0 | C6: -Users-matthewkerns-workspace-ecommerce-ecommerce-tools-brand-systems-idea-brand-coach | D6: 77 | E6: 0.647 | F6: O7
A7: 46155 | B7: 752b7d11 | C7: -Users-matthewkerns-workspace-ecommerce-ecommerce-tools-brand-systems-idea-brand-coach | D7: 438 | E7: 1.355 | F7: O7
A8: 46136 | B8: 53d8367d | C8: -Users-matthewkerns-workspace-ecommerce-ecommerce-tools-brand-systems-idea-brand-coach | D8: 52 | E8: 0.633 | F8: O7
A9: 46136 | B9: a754fbda | C9: -Users-matthewkerns-workspace-ecommerce-ecommerce-tools-brand-systems-idea-brand-coach | D9: 41 | E9: 0.34 | F9: O7
D10: TOTAL | E10: =SUM(E2:E9)
B11: Active time = sum of inter-event gaps, capped at 15 min/gap. Under-counts: subagent work is not in top-level sessions.

Sheet Change Log
A1: Date | B1: Version | C1: Change
A2: 46167 | B2: v1.0 | C2: Initial build: 7 strategic objectives; time triangulated from Clockify (logged) + Fathom (meeting) + JSONL (estimated).
