Workbook

Sheet Summary
A1: Summary — feature readiness by launch phase
A2: Live rollup from the Features sheet. Status column derives on-track / at-risk / blocked from the underlying data.
A4: phase | B4: features_required | C4: complete | D4: in_progress | E4: blocked | F4: not_started | G4: percent_complete | H4: status
A5: Alpha | B5: =COUNTIF('Features'!$E$3:$E$72,"Alpha") | C5: =COUNTIFS('Features'!$E$3:$E$72,"Alpha",'Features'!$G$3:$G$72,"complete") | D5: =COUNTIFS('Features'!$E$3:$E$72,"Alpha",'Features'!$G$3:$G$72,"in_progress")+COUNTIFS('Features'!$E$3:$E$72,"Alpha",'Features'!$G$3:$G$72,"in_review") | E5: =COUNTIFS('Features'!$E$3:$E$72,"Alpha",'Features'!$G$3:$G$72,"blocked") | F5: =COUNTIFS('Features'!$E$3:$E$72,"Alpha",'Features'!$G$3:$G$72,"not_started") | G5: =IFERROR(ROUND(SUMIFS('Features'!$H$3:$H$72,'Features'!$E$3:$E$72,"Alpha")/(B5*100),3),0) | H5: =IF(E5>0,"BLOCKED",IF(G5>=0.9,"ON-TRACK",IF(G5>=0.5,"AT-RISK",IF(B5=0,"N/A","AT-RISK"))))
A6: Beta | B6: =COUNTIF('Features'!$E$3:$E$72,"Beta") | C6: =COUNTIFS('Features'!$E$3:$E$72,"Beta",'Features'!$G$3:$G$72,"complete") | D6: =COUNTIFS('Features'!$E$3:$E$72,"Beta",'Features'!$G$3:$G$72,"in_progress")+COUNTIFS('Features'!$E$3:$E$72,"Beta",'Features'!$G$3:$G$72,"in_review") | E6: =COUNTIFS('Features'!$E$3:$E$72,"Beta",'Features'!$G$3:$G$72,"blocked") | F6: =COUNTIFS('Features'!$E$3:$E$72,"Beta",'Features'!$G$3:$G$72,"not_started") | G6: =IFERROR(ROUND(SUMIFS('Features'!$H$3:$H$72,'Features'!$E$3:$E$72,"Beta")/(B6*100),3),0) | H6: =IF(E6>0,"BLOCKED",IF(G6>=0.9,"ON-TRACK",IF(G6>=0.5,"AT-RISK",IF(B6=0,"N/A","AT-RISK"))))
A7: GA | B7: =COUNTIF('Features'!$E$3:$E$72,"GA") | C7: =COUNTIFS('Features'!$E$3:$E$72,"GA",'Features'!$G$3:$G$72,"complete") | D7: =COUNTIFS('Features'!$E$3:$E$72,"GA",'Features'!$G$3:$G$72,"in_progress")+COUNTIFS('Features'!$E$3:$E$72,"GA",'Features'!$G$3:$G$72,"in_review") | E7: =COUNTIFS('Features'!$E$3:$E$72,"GA",'Features'!$G$3:$G$72,"blocked") | F7: =COUNTIFS('Features'!$E$3:$E$72,"GA",'Features'!$G$3:$G$72,"not_started") | G7: =IFERROR(ROUND(SUMIFS('Features'!$H$3:$H$72,'Features'!$E$3:$E$72,"GA")/(B7*100),3),0) | H7: =IF(E7>0,"BLOCKED",IF(G7>=0.9,"ON-TRACK",IF(G7>=0.5,"AT-RISK",IF(B7=0,"N/A","AT-RISK"))))
A8: Post-GA | B8: =COUNTIF('Features'!$E$3:$E$72,"Post-GA") | C8: =COUNTIFS('Features'!$E$3:$E$72,"Post-GA",'Features'!$G$3:$G$72,"complete") | D8: =COUNTIFS('Features'!$E$3:$E$72,"Post-GA",'Features'!$G$3:$G$72,"in_progress")+COUNTIFS('Features'!$E$3:$E$72,"Post-GA",'Features'!$G$3:$G$72,"in_review") | E8: =COUNTIFS('Features'!$E$3:$E$72,"Post-GA",'Features'!$G$3:$G$72,"blocked") | F8: =COUNTIFS('Features'!$E$3:$E$72,"Post-GA",'Features'!$G$3:$G$72,"not_started") | G8: =IFERROR(ROUND(SUMIFS('Features'!$H$3:$H$72,'Features'!$E$3:$E$72,"Post-GA")/(B8*100),3),0) | H8: =IF(E8>0,"BLOCKED",IF(G8>=0.9,"ON-TRACK",IF(G8>=0.5,"AT-RISK",IF(B8=0,"N/A","AT-RISK"))))
A10: Earliest blocker (first feature with status = blocked)
A11: =IFERROR(INDEX('Features'!A3:A72,MATCH("blocked",'Features'!$G$3:$G$72,0)),"None") | B11: =IFERROR(INDEX('Features'!B3:B72,MATCH("blocked",'Features'!$G$3:$G$72,0)),"None") | C11: =IFERROR(INDEX('Features'!E3:E72,MATCH("blocked",'Features'!$G$3:$G$72,0)),"") | D11: =IFERROR(INDEX('Features'!I3:I72,MATCH("blocked",'Features'!$G$3:$G$72,0)),"")

Sheet Problems
A1: Problems — the grand-vision list, mapped to features
A2: Each problem is mapped to the features that help solve it. fulfilment_status derives from the status of mapped features. alpha_testable = whether Alpha-stage features alone are enough to validate this problem with testers.
A4: problem_id | B4: problem_statement | C4: earliest_phase_solvable | D4: alpha_testable | E4: mapped_features | F4: feature_count | G4: complete_or_review_count | H4: fulfilment_status | I4: notes
A5: P-001 | B5: Generic AI doesn't know my customer deeply enough. | C5: Alpha | D5: Yes | E5: F-004,F-005,F-006,F-007,F-008,F-009,F-012,F-022,F-058,F-060 | F5: 10 | G5: =(COUNTIFS('Features'!$A$3:$A$72,"F-004",'Features'!$G$3:$G$72,"complete")+COUNTIFS('Features'!$A$3:$A$72,"F-004",'Features'!$G$3:$G$72,"in_review")+COUNTIFS('Features'!$A$3:$A$72,"F-005",'Features'!$G$3:$G$72,"complete")+COUNTIFS('Features'!$A$3:$A$72,"F-005",'Features'!$G$3:$G$72,"in_review")+COUNTIFS('Features'!$A$3:$A$72,"F-006",'Features'!$G$3:$G$72,"complete")+COUNTIFS('Features'!$A$3:$A$72,"F-006",'Features'!$G$3:$G$72,"in_review")+COUNTIFS('Features'!$A$3:$A$72,"F-007",'Features'!$G$3:$G$72,"complete")+COUNTIFS('Features'!$A$3:$A$72,"F-007",'Features'!$G$3:$G$72,"in_review")+COUNTIFS('Features'!$A$3:$A$72,"F-008",'Features'!$G$3:$G$72,"complete")+COUNTIFS('Features'!$A$3:$A$72,"F-008",'Features'!$G$3:$G$72,"in_review")+COUNTIFS('Features'!$A$3:$A$72,"F-009",'Features'!$G$3:$G$72,"complete")+COUNTIFS('Features'!$A$3:$A$72,"F-009",'Features'!$G$3:$G$72,"in_review")+COUNTIFS('Features'!$A$3:$A$72,"F-012",'Features'!$G$3:$G$72,"complete")+COUNTIFS('Features'!$A$3:$A$72,"F-012",'Features'!$G$3:$G$72,"in_review")+COUNTIFS('Features'!$A$3:$A$72,"F-022",'Features'!$G$3:$G$72,"complete")+COUNTIFS('Features'!$A$3:$A$72,"F-022",'Features'!$G$3:$G$72,"in_review")+COUNTIFS('Features'!$A$3:$A$72,"F-058",'Features'!$G$3:$G$72,"complete")+COUNTIFS('Features'!$A$3:$A$72,"F-058",'Features'!$G$3:$G$72,"in_review")+COUNTIFS('Features'!$A$3:$A$72,"F-060",'Features'!$G$3:$G$72,"complete")+COUNTIFS('Features'!$A$3:$A$72,"F-060",'Features'!$G$3:$G$72,"in_review")) | H5: =IF((COUNTIFS('Features'!$A$3:$A$72,"F-004",'Features'!$G$3:$G$72,"blocked")+COUNTIFS('Features'!$A$3:$A$72,"F-005",'Features'!$G$3:$G$72,"blocked")+COUNTIFS('Features'!$A$3:$A$72,"F-006",'Features'!$G$3:$G$72,"blocked")+COUNTIFS('Features'!$A$3:$A$72,"F-007",'Features'!$G$3:$G$72,"blocked")+COUNTIFS('Features'!$A$3:$A$72,"F-008",'Features'!$G$3:$G$72,"blocked")+COUNTIFS('Features'!$A$3:$A$72,"F-009",'Features'!$G$3:$G$72,"blocked")+COUNTIFS('Features'!$A$3:$A$72,"F-012",'Features'!$G$3:$G$72,"blocked")+COUNTIFS('Features'!$A$3:$A$72,"F-022",'Features'!$G$3:$G$72,"blocked")+COUNTIFS('Features'!$A$3:$A$72,"F-058",'Features'!$G$3:$G$72,"blocked")+COUNTIFS('Features'!$A$3:$A$72,"F-060",'Features'!$G$3:$G$72,"blocked"))>0,"BLOCKED — see mapped features",IF((COUNTIFS('Features'!$A$3:$A$72,"F-004",'Features'!$G$3:$G$72,"complete")+COUNTIFS('Features'!$A$3:$A$72,"F-004",'Features'!$G$3:$G$72,"in_review")+COUNTIFS('Features'!$A$3:$A$72,"F-005",'Features'!$G$3:$G$72,"complete")+COUNTIFS('Features'!$A$3:$A$72,"F-005",'Features'!$G$3:$G$72,"in_review")+COUNTIFS('Features'!$A$3:$A$72,"F-006",'Features'!$G$3:$G$72,"complete")+COUNTIFS('Features'!$A$3:$A$72,"F-006",'Features'!$G$3:$G$72,"in_review")+COUNTIFS('Features'!$A$3:$A$72,"F-007",'Features'!$G$3:$G$72,"complete")+COUNTIFS('Features'!$A$3:$A$72,"F-007",'Features'!$G$3:$G$72,"in_review")+COUNTIFS('Features'!$A$3:$A$72,"F-008",'Features'!$G$3:$G$72,"complete")+COUNTIFS('Features'!$A$3:$A$72,"F-008",'Features'!$G$3:$G$72,"in_review")+COUNTIFS('Features'!$A$3:$A$72,"F-009",'Features'!$G$3:$G$72,"complete")+COUNTIFS('Features'!$A$3:$A$72,"F-009",'Features'!$G$3:$G$72,"in_review")+COUNTIFS('Features'!$A$3:$A$72,"F-012",'Features'!$G$3:$G$72,"complete")+COUNTIFS('Features'!$A$3:$A$72,"F-012",'Features'!$G$3:$G$72,"in_review")+COUNTIFS('Features'!$A$3:$A$72,"F-022",'Features'!$G$3:$G$72,"complete")+COUNTIFS('Features'!$A$3:$A$72,"F-022",'Features'!$G$3:$G$72,"in_review")+COUNTIFS('Features'!$A$3:$A$72,"F-058",'Features'!$G$3:$G$72,"complete")+COUNTIFS('Features'!$A$3:$A$72,"F-058",'Features'!$G$3:$G$72,"in_review")+COUNTIFS('Features'!$A$3:$A$72,"F-060",'Features'!$G$3:$G$72,"complete")+COUNTIFS('Features'!$A$3:$A$72,"F-060",'Features'!$G$3:$G$72,"in_review"))=10,"MET",IF((COUNTIFS('Features'!$A$3:$A$72,"F-004",'Features'!$G$3:$G$72,"complete")+COUNTIFS('Features'!$A$3:$A$72,"F-004",'Features'!$G$3:$G$72,"in_review")+COUNTIFS('Features'!$A$3:$A$72,"F-005",'Features'!$G$3:$G$72,"complete")+COUNTIFS('Features'!$A$3:$A$72,"F-005",'Features'!$G$3:$G$72,"in_review")+COUNTIFS('Features'!$A$3:$A$72,"F-006",'Features'!$G$3:$G$72,"complete")+COUNTIFS('Features'!$A$3:$A$72,"F-006",'Features'!$G$3:$G$72,"in_review")+COUNTIFS('Features'!$A$3:$A$72,"F-007",'Features'!$G$3:$G$72,"complete")+COUNTIFS('Features'!$A$3:$A$72,"F-007",'Features'!$G$3:$G$72,"in_review")+COUNTIFS('Features'!$A$3:$A$72,"F-008",'Features'!$G$3:$G$72,"complete")+COUNTIFS('Features'!$A$3:$A$72,"F-008",'Features'!$G$3:$G$72,"in_review")+COUNTIFS('Features'!$A$3:$A$72,"F-009",'Features'!$G$3:$G$72,"complete")+COUNTIFS('Features'!$A$3:$A$72,"F-009",'Features'!$G$3:$G$72,"in_review")+COUNTIFS('Features'!$A$3:$A$72,"F-012",'Features'!$G$3:$G$72,"complete")+COUNTIFS('Features'!$A$3:$A$72,"F-012",'Features'!$G$3:$G$72,"in_review")+COUNTIFS('Features'!$A$3:$A$72,"F-022",'Features'!$G$3:$G$72,"complete")+COUNTIFS('Features'!$A$3:$A$72,"F-022",'Features'!$G$3:$G$72,"in_review")+COUNTIFS('Features'!$A$3:$A$72,"F-058",'Features'!$G$3:$G$72,"complete")+COUNTIFS('Features'!$A$3:$A$72,"F-058",'Features'!$G$3:$G$72,"in_review")+COUNTIFS('Features'!$A$3:$A$72,"F-060",'Features'!$G$3:$G$72,"complete")+COUNTIFS('Features'!$A$3:$A$72,"F-060",'Features'!$G$3:$G$72,"in_review"))=0,"OPEN — 0 of 10","PARTIAL — "&(COUNTIFS('Features'!$A$3:$A$72,"F-004",'Features'!$G$3:$G$72,"complete")+COUNTIFS('Features'!$A$3:$A$72,"F-004",'Features'!$G$3:$G$72,"in_review")+COUNTIFS('Features'!$A$3:$A$72,"F-005",'Features'!$G$3:$G$72,"complete")+COUNTIFS('Features'!$A$3:$A$72,"F-005",'Features'!$G$3:$G$72,"in_review")+COUNTIFS('Features'!$A$3:$A$72,"F-006",'Features'!$G$3:$G$72,"complete")+COUNTIFS('Features'!$A$3:$A$72,"F-006",'Features'!$G$3:$G$72,"in_review")+COUNTIFS('Features'!$A$3:$A$72,"F-007",'Features'!$G$3:$G$72,"complete")+COUNTIFS('Features'!$A$3:$A$72,"F-007",'Features'!$G$3:$G$72,"in_review")+COUNTIFS('Features'!$A$3:$A$72,"F-008",'Features'!$G$3:$G$72,"complete")+COUNTIFS('Features'!$A$3:$A$72,"F-008",'Features'!$G$3:$G$72,"in_review")+COUNTIFS('Features'!$A$3:$A$72,"F-009",'Features'!$G$3:$G$72,"complete")+COUNTIFS('Features'!$A$3:$A$72,"F-009",'Features'!$G$3:$G$72,"in_review")+COUNTIFS('Features'!$A$3:$A$72,"F-012",'Features'!$G$3:$G$72,"complete")+COUNTIFS('Features'!$A$3:$A$72,"F-012",'Features'!$G$3:$G$72,"in_review")+COUNTIFS('Features'!$A$3:$A$72,"F-022",'Features'!$G$3:$G$72,"complete")+COUNTIFS('Features'!$A$3:$A$72,"F-022",'Features'!$G$3:$G$72,"in_review")+COUNTIFS('Features'!$A$3:$A$72,"F-058",'Features'!$G$3:$G$72,"complete")+COUNTIFS('Features'!$A$3:$A$72,"F-058",'Features'!$G$3:$G$72,"in_review")+COUNTIFS('Features'!$A$3:$A$72,"F-060",'Features'!$G$3:$G$72,"complete")+COUNTIFS('Features'!$A$3:$A$72,"F-060",'Features'!$G$3:$G$72,"in_review"))&" of 10"))) | I5: Core Alpha thesis: Avatar Builder + Forensic Canvas produce a depth of customer understanding generic prompting can't reach. F-022 (Coach mode) extends this in Beta. GEN3 (2026-05-25): = cannot articulate what the customer is actually buying → The Signature (F-060) is the answer; the Decision Trigger (F-058) sharpens it. MVP-critical, validate first. Free tier.
A6: P-002 | B6: I don't know what to ask myself about my customer. | C6: Alpha | D6: Yes | E6: F-001,F-004,F-005,F-006,F-007,F-009,F-060,F-061,F-062 | F6: 9 | G6: =(COUNTIFS('Features'!$A$3:$A$72,"F-001",'Features'!$G$3:$G$72,"complete")+COUNTIFS('Features'!$A$3:$A$72,"F-001",'Features'!$G$3:$G$72,"in_review")+COUNTIFS('Features'!$A$3:$A$72,"F-004",'Features'!$G$3:$G$72,"complete")+COUNTIFS('Features'!$A$3:$A$72,"F-004",'Features'!$G$3:$G$72,"in_review")+COUNTIFS('Features'!$A$3:$A$72,"F-005",'Features'!$G$3:$G$72,"complete")+COUNTIFS('Features'!$A$3:$A$72,"F-005",'Features'!$G$3:$G$72,"in_review")+COUNTIFS('Features'!$A$3:$A$72,"F-006",'Features'!$G$3:$G$72,"complete")+COUNTIFS('Features'!$A$3:$A$72,"F-006",'Features'!$G$3:$G$72,"in_review")+COUNTIFS('Features'!$A$3:$A$72,"F-007",'Features'!$G$3:$G$72,"complete")+COUNTIFS('Features'!$A$3:$A$72,"F-007",'Features'!$G$3:$G$72,"in_review")+COUNTIFS('Features'!$A$3:$A$72,"F-009",'Features'!$G$3:$G$72,"complete")+COUNTIFS('Features'!$A$3:$A$72,"F-009",'Features'!$G$3:$G$72,"in_review")+COUNTIFS('Features'!$A$3:$A$72,"F-060",'Features'!$G$3:$G$72,"complete")+COUNTIFS('Features'!$A$3:$A$72,"F-060",'Features'!$G$3:$G$72,"in_review")+COUNTIFS('Features'!$A$3:$A$72,"F-061",'Features'!$G$3:$G$72,"complete")+COUNTIFS('Features'!$A$3:$A$72,"F-061",'Features'!$G$3:$G$72,"in_review")+COUNTIFS('Features'!$A$3:$A$72,"F-062",'Features'!$G$3:$G$72,"complete")+COUNTIFS('Features'!$A$3:$A$72,"F-062",'Features'!$G$3:$G$72,"in_review")) | H6: =IF((COUNTIFS('Features'!$A$3:$A$72,"F-001",'Features'!$G$3:$G$72,"blocked")+COUNTIFS('Features'!$A$3:$A$72,"F-004",'Features'!$G$3:$G$72,"blocked")+COUNTIFS('Features'!$A$3:$A$72,"F-005",'Features'!$G$3:$G$72,"blocked")+COUNTIFS('Features'!$A$3:$A$72,"F-006",'Features'!$G$3:$G$72,"blocked")+COUNTIFS('Features'!$A$3:$A$72,"F-007",'Features'!$G$3:$G$72,"blocked")+COUNTIFS('Features'!$A$3:$A$72,"F-009",'Features'!$G$3:$G$72,"blocked")+COUNTIFS('Features'!$A$3:$A$72,"F-060",'Features'!$G$3:$G$72,"blocked")+COUNTIFS('Features'!$A$3:$A$72,"F-061",'Features'!$G$3:$G$72,"blocked")+COUNTIFS('Features'!$A$3:$A$72,"F-062",'Features'!$G$3:$G$72,"blocked"))>0,"BLOCKED — see mapped features",IF((COUNTIFS('Features'!$A$3:$A$72,"F-001",'Features'!$G$3:$G$72,"complete")+COUNTIFS('Features'!$A$3:$A$72,"F-001",'Features'!$G$3:$G$72,"in_review")+COUNTIFS('Features'!$A$3:$A$72,"F-004",'Features'!$G$3:$G$72,"complete")+COUNTIFS('Features'!$A$3:$A$72,"F-004",'Features'!$G$3:$G$72,"in_review")+COUNTIFS('Features'!$A$3:$A$72,"F-005",'Features'!$G$3:$G$72,"complete")+COUNTIFS('Features'!$A$3:$A$72,"F-005",'Features'!$G$3:$G$72,"in_review")+COUNTIFS('Features'!$A$3:$A$72,"F-006",'Features'!$G$3:$G$72,"complete")+COUNTIFS('Features'!$A$3:$A$72,"F-006",'Features'!$G$3:$G$72,"in_review")+COUNTIFS('Features'!$A$3:$A$72,"F-007",'Features'!$G$3:$G$72,"complete")+COUNTIFS('Features'!$A$3:$A$72,"F-007",'Features'!$G$3:$G$72,"in_review")+COUNTIFS('Features'!$A$3:$A$72,"F-009",'Features'!$G$3:$G$72,"complete")+COUNTIFS('Features'!$A$3:$A$72,"F-009",'Features'!$G$3:$G$72,"in_review")+COUNTIFS('Features'!$A$3:$A$72,"F-060",'Features'!$G$3:$G$72,"complete")+COUNTIFS('Features'!$A$3:$A$72,"F-060",'Features'!$G$3:$G$72,"in_review")+COUNTIFS('Features'!$A$3:$A$72,"F-061",'Features'!$G$3:$G$72,"complete")+COUNTIFS('Features'!$A$3:$A$72,"F-061",'Features'!$G$3:$G$72,"in_review")+COUNTIFS('Features'!$A$3:$A$72,"F-062",'Features'!$G$3:$G$72,"complete")+COUNTIFS('Features'!$A$3:$A$72,"F-062",'Features'!$G$3:$G$72,"in_review"))=9,"MET",IF((COUNTIFS('Features'!$A$3:$A$72,"F-001",'Features'!$G$3:$G$72,"complete")+COUNTIFS('Features'!$A$3:$A$72,"F-001",'Features'!$G$3:$G$72,"in_review")+COUNTIFS('Features'!$A$3:$A$72,"F-004",'Features'!$G$3:$G$72,"complete")+COUNTIFS('Features'!$A$3:$A$72,"F-004",'Features'!$G$3:$G$72,"in_review")+COUNTIFS('Features'!$A$3:$A$72,"F-005",'Features'!$G$3:$G$72,"complete")+COUNTIFS('Features'!$A$3:$A$72,"F-005",'Features'!$G$3:$G$72,"in_review")+COUNTIFS('Features'!$A$3:$A$72,"F-006",'Features'!$G$3:$G$72,"complete")+COUNTIFS('Features'!$A$3:$A$72,"F-006",'Features'!$G$3:$G$72,"in_review")+COUNTIFS('Features'!$A$3:$A$72,"F-007",'Features'!$G$3:$G$72,"complete")+COUNTIFS('Features'!$A$3:$A$72,"F-007",'Features'!$G$3:$G$72,"in_review")+COUNTIFS('Features'!$A$3:$A$72,"F-009",'Features'!$G$3:$G$72,"complete")+COUNTIFS('Features'!$A$3:$A$72,"F-009",'Features'!$G$3:$G$72,"in_review")+COUNTIFS('Features'!$A$3:$A$72,"F-060",'Features'!$G$3:$G$72,"complete")+COUNTIFS('Features'!$A$3:$A$72,"F-060",'Features'!$G$3:$G$72,"in_review")+COUNTIFS('Features'!$A$3:$A$72,"F-061",'Features'!$G$3:$G$72,"complete")+COUNTIFS('Features'!$A$3:$A$72,"F-061",'Features'!$G$3:$G$72,"in_review")+COUNTIFS('Features'!$A$3:$A$72,"F-062",'Features'!$G$3:$G$72,"complete")+COUNTIFS('Features'!$A$3:$A$72,"F-062",'Features'!$G$3:$G$72,"in_review"))=0,"OPEN — 0 of 9","PARTIAL — "&(COUNTIFS('Features'!$A$3:$A$72,"F-001",'Features'!$G$3:$G$72,"complete")+COUNTIFS('Features'!$A$3:$A$72,"F-001",'Features'!$G$3:$G$72,"in_review")+COUNTIFS('Features'!$A$3:$A$72,"F-004",'Features'!$G$3:$G$72,"complete")+COUNTIFS('Features'!$A$3:$A$72,"F-004",'Features'!$G$3:$G$72,"in_review")+COUNTIFS('Features'!$A$3:$A$72,"F-005",'Features'!$G$3:$G$72,"complete")+COUNTIFS('Features'!$A$3:$A$72,"F-005",'Features'!$G$3:$G$72,"in_review")+COUNTIFS('Features'!$A$3:$A$72,"F-006",'Features'!$G$3:$G$72,"complete")+COUNTIFS('Features'!$A$3:$A$72,"F-006",'Features'!$G$3:$G$72,"in_review")+COUNTIFS('Features'!$A$3:$A$72,"F-007",'Features'!$G$3:$G$72,"complete")+COUNTIFS('Features'!$A$3:$A$72,"F-007",'Features'!$G$3:$G$72,"in_review")+COUNTIFS('Features'!$A$3:$A$72,"F-009",'Features'!$G$3:$G$72,"complete")+COUNTIFS('Features'!$A$3:$A$72,"F-009",'Features'!$G$3:$G$72,"in_review")+COUNTIFS('Features'!$A$3:$A$72,"F-060",'Features'!$G$3:$G$72,"complete")+COUNTIFS('Features'!$A$3:$A$72,"F-060",'Features'!$G$3:$G$72,"in_review")+COUNTIFS('Features'!$A$3:$A$72,"F-061",'Features'!$G$3:$G$72,"complete")+COUNTIFS('Features'!$A$3:$A$72,"F-061",'Features'!$G$3:$G$72,"in_review")+COUNTIFS('Features'!$A$3:$A$72,"F-062",'Features'!$G$3:$G$72,"complete")+COUNTIFS('Features'!$A$3:$A$72,"F-062",'Features'!$G$3:$G$72,"in_review"))&" of 9"))) | I6: 10-Q conversation + 4 Avatar Builder sections provide the inquiry structure. F-009 'Think About This' mode explicitly generates reflective questions per field.
A7: P-003 | B7: My brand strategy doc is shallow or doesn't exist. | C7: Alpha | D7: Partial | E7: F-003,F-008,F-023,F-053 | F7: 4 | G7: =(COUNTIFS('Features'!$A$3:$A$72,"F-003",'Features'!$G$3:$G$72,"complete")+COUNTIFS('Features'!$A$3:$A$72,"F-003",'Features'!$G$3:$G$72,"in_review")+COUNTIFS('Features'!$A$3:$A$72,"F-008",'Features'!$G$3:$G$72,"complete")+COUNTIFS('Features'!$A$3:$A$72,"F-008",'Features'!$G$3:$G$72,"in_review")+COUNTIFS('Features'!$A$3:$A$72,"F-023",'Features'!$G$3:$G$72,"complete")+COUNTIFS('Features'!$A$3:$A$72,"F-023",'Features'!$G$3:$G$72,"in_review")+COUNTIFS('Features'!$A$3:$A$72,"F-053",'Features'!$G$3:$G$72,"complete")+COUNTIFS('Features'!$A$3:$A$72,"F-053",'Features'!$G$3:$G$72,"in_review")) | H7: =IF((COUNTIFS('Features'!$A$3:$A$72,"F-003",'Features'!$G$3:$G$72,"blocked")+COUNTIFS('Features'!$A$3:$A$72,"F-008",'Features'!$G$3:$G$72,"blocked")+COUNTIFS('Features'!$A$3:$A$72,"F-023",'Features'!$G$3:$G$72,"blocked")+COUNTIFS('Features'!$A$3:$A$72,"F-053",'Features'!$G$3:$G$72,"blocked"))>0,"BLOCKED — see mapped features",IF((COUNTIFS('Features'!$A$3:$A$72,"F-003",'Features'!$G$3:$G$72,"complete")+COUNTIFS('Features'!$A$3:$A$72,"F-003",'Features'!$G$3:$G$72,"in_review")+COUNTIFS('Features'!$A$3:$A$72,"F-008",'Features'!$G$3:$G$72,"complete")+COUNTIFS('Features'!$A$3:$A$72,"F-008",'Features'!$G$3:$G$72,"in_review")+COUNTIFS('Features'!$A$3:$A$72,"F-023",'Features'!$G$3:$G$72,"complete")+COUNTIFS('Features'!$A$3:$A$72,"F-023",'Features'!$G$3:$G$72,"in_review")+COUNTIFS('Features'!$A$3:$A$72,"F-053",'Features'!$G$3:$G$72,"complete")+COUNTIFS('Features'!$A$3:$A$72,"F-053",'Features'!$G$3:$G$72,"in_review"))=4,"MET",IF((COUNTIFS('Features'!$A$3:$A$72,"F-003",'Features'!$G$3:$G$72,"complete")+COUNTIFS('Features'!$A$3:$A$72,"F-003",'Features'!$G$3:$G$72,"in_review")+COUNTIFS('Features'!$A$3:$A$72,"F-008",'Features'!$G$3:$G$72,"complete")+COUNTIFS('Features'!$A$3:$A$72,"F-008",'Features'!$G$3:$G$72,"in_review")+COUNTIFS('Features'!$A$3:$A$72,"F-023",'Features'!$G$3:$G$72,"complete")+COUNTIFS('Features'!$A$3:$A$72,"F-023",'Features'!$G$3:$G$72,"in_review")+COUNTIFS('Features'!$A$3:$A$72,"F-053",'Features'!$G$3:$G$72,"complete")+COUNTIFS('Features'!$A$3:$A$72,"F-053",'Features'!$G$3:$G$72,"in_review"))=0,"OPEN — 0 of 4","PARTIAL — "&(COUNTIFS('Features'!$A$3:$A$72,"F-003",'Features'!$G$3:$G$72,"complete")+COUNTIFS('Features'!$A$3:$A$72,"F-003",'Features'!$G$3:$G$72,"in_review")+COUNTIFS('Features'!$A$3:$A$72,"F-008",'Features'!$G$3:$G$72,"complete")+COUNTIFS('Features'!$A$3:$A$72,"F-008",'Features'!$G$3:$G$72,"in_review")+COUNTIFS('Features'!$A$3:$A$72,"F-023",'Features'!$G$3:$G$72,"complete")+COUNTIFS('Features'!$A$3:$A$72,"F-023",'Features'!$G$3:$G$72,"in_review")+COUNTIFS('Features'!$A$3:$A$72,"F-053",'Features'!$G$3:$G$72,"complete")+COUNTIFS('Features'!$A$3:$A$72,"F-053",'Features'!$G$3:$G$72,"in_review"))&" of 4"))) | I7: F-008 (Forensic Canvas via generate-brand-strategy-document) is the primary fulfilment — substantially shipped. Polished Word export (F-023) and multi-angle (F-053) are Beta extensions.
A8: P-004 | B8: My copy and creative aren't grounded in strategy. | C8: Beta | D8: No | E8: F-008,F-020,F-021,F-055 | F8: 4 | G8: =(COUNTIFS('Features'!$A$3:$A$72,"F-008",'Features'!$G$3:$G$72,"complete")+COUNTIFS('Features'!$A$3:$A$72,"F-008",'Features'!$G$3:$G$72,"in_review")+COUNTIFS('Features'!$A$3:$A$72,"F-020",'Features'!$G$3:$G$72,"complete")+COUNTIFS('Features'!$A$3:$A$72,"F-020",'Features'!$G$3:$G$72,"in_review")+COUNTIFS('Features'!$A$3:$A$72,"F-021",'Features'!$G$3:$G$72,"complete")+COUNTIFS('Features'!$A$3:$A$72,"F-021",'Features'!$G$3:$G$72,"in_review")+COUNTIFS('Features'!$A$3:$A$72,"F-055",'Features'!$G$3:$G$72,"complete")+COUNTIFS('Features'!$A$3:$A$72,"F-055",'Features'!$G$3:$G$72,"in_review")) | H8: =IF((COUNTIFS('Features'!$A$3:$A$72,"F-008",'Features'!$G$3:$G$72,"blocked")+COUNTIFS('Features'!$A$3:$A$72,"F-020",'Features'!$G$3:$G$72,"blocked")+COUNTIFS('Features'!$A$3:$A$72,"F-021",'Features'!$G$3:$G$72,"blocked")+COUNTIFS('Features'!$A$3:$A$72,"F-055",'Features'!$G$3:$G$72,"blocked"))>0,"BLOCKED — see mapped features",IF((COUNTIFS('Features'!$A$3:$A$72,"F-008",'Features'!$G$3:$G$72,"complete")+COUNTIFS('Features'!$A$3:$A$72,"F-008",'Features'!$G$3:$G$72,"in_review")+COUNTIFS('Features'!$A$3:$A$72,"F-020",'Features'!$G$3:$G$72,"complete")+COUNTIFS('Features'!$A$3:$A$72,"F-020",'Features'!$G$3:$G$72,"in_review")+COUNTIFS('Features'!$A$3:$A$72,"F-021",'Features'!$G$3:$G$72,"complete")+COUNTIFS('Features'!$A$3:$A$72,"F-021",'Features'!$G$3:$G$72,"in_review")+COUNTIFS('Features'!$A$3:$A$72,"F-055",'Features'!$G$3:$G$72,"complete")+COUNTIFS('Features'!$A$3:$A$72,"F-055",'Features'!$G$3:$G$72,"in_review"))=4,"MET",IF((COUNTIFS('Features'!$A$3:$A$72,"F-008",'Features'!$G$3:$G$72,"complete")+COUNTIFS('Features'!$A$3:$A$72,"F-008",'Features'!$G$3:$G$72,"in_review")+COUNTIFS('Features'!$A$3:$A$72,"F-020",'Features'!$G$3:$G$72,"complete")+COUNTIFS('Features'!$A$3:$A$72,"F-020",'Features'!$G$3:$G$72,"in_review")+COUNTIFS('Features'!$A$3:$A$72,"F-021",'Features'!$G$3:$G$72,"complete")+COUNTIFS('Features'!$A$3:$A$72,"F-021",'Features'!$G$3:$G$72,"in_review")+COUNTIFS('Features'!$A$3:$A$72,"F-055",'Features'!$G$3:$G$72,"complete")+COUNTIFS('Features'!$A$3:$A$72,"F-055",'Features'!$G$3:$G$72,"in_review"))=0,"OPEN — 0 of 4","PARTIAL — "&(COUNTIFS('Features'!$A$3:$A$72,"F-008",'Features'!$G$3:$G$72,"complete")+COUNTIFS('Features'!$A$3:$A$72,"F-008",'Features'!$G$3:$G$72,"in_review")+COUNTIFS('Features'!$A$3:$A$72,"F-020",'Features'!$G$3:$G$72,"complete")+COUNTIFS('Features'!$A$3:$A$72,"F-020",'Features'!$G$3:$G$72,"in_review")+COUNTIFS('Features'!$A$3:$A$72,"F-021",'Features'!$G$3:$G$72,"complete")+COUNTIFS('Features'!$A$3:$A$72,"F-021",'Features'!$G$3:$G$72,"in_review")+COUNTIFS('Features'!$A$3:$A$72,"F-055",'Features'!$G$3:$G$72,"complete")+COUNTIFS('Features'!$A$3:$A$72,"F-055",'Features'!$G$3:$G$72,"in_review"))&" of 4"))) | I8: Requires Create mode outputs (F-020 Amazon, F-021 Voice Guide, F-055 Design brief). None ship in Alpha. The canvas (F-008) is the anchor but not the deliverable for this problem.
A9: P-005 | B9: My customer's actual language doesn't make it into my copy. | C9: Beta | D9: Partial | E9: F-007,F-008,F-020,F-021,F-063 | F9: 5 | G9: =(COUNTIFS('Features'!$A$3:$A$72,"F-007",'Features'!$G$3:$G$72,"complete")+COUNTIFS('Features'!$A$3:$A$72,"F-007",'Features'!$G$3:$G$72,"in_review")+COUNTIFS('Features'!$A$3:$A$72,"F-008",'Features'!$G$3:$G$72,"complete")+COUNTIFS('Features'!$A$3:$A$72,"F-008",'Features'!$G$3:$G$72,"in_review")+COUNTIFS('Features'!$A$3:$A$72,"F-020",'Features'!$G$3:$G$72,"complete")+COUNTIFS('Features'!$A$3:$A$72,"F-020",'Features'!$G$3:$G$72,"in_review")+COUNTIFS('Features'!$A$3:$A$72,"F-021",'Features'!$G$3:$G$72,"complete")+COUNTIFS('Features'!$A$3:$A$72,"F-021",'Features'!$G$3:$G$72,"in_review")+COUNTIFS('Features'!$A$3:$A$72,"F-063",'Features'!$G$3:$G$72,"complete")+COUNTIFS('Features'!$A$3:$A$72,"F-063",'Features'!$G$3:$G$72,"in_review")) | H9: =IF((COUNTIFS('Features'!$A$3:$A$72,"F-007",'Features'!$G$3:$G$72,"blocked")+COUNTIFS('Features'!$A$3:$A$72,"F-008",'Features'!$G$3:$G$72,"blocked")+COUNTIFS('Features'!$A$3:$A$72,"F-020",'Features'!$G$3:$G$72,"blocked")+COUNTIFS('Features'!$A$3:$A$72,"F-021",'Features'!$G$3:$G$72,"blocked")+COUNTIFS('Features'!$A$3:$A$72,"F-063",'Features'!$G$3:$G$72,"blocked"))>0,"BLOCKED — see mapped features",IF((COUNTIFS('Features'!$A$3:$A$72,"F-007",'Features'!$G$3:$G$72,"complete")+COUNTIFS('Features'!$A$3:$A$72,"F-007",'Features'!$G$3:$G$72,"in_review")+COUNTIFS('Features'!$A$3:$A$72,"F-008",'Features'!$G$3:$G$72,"complete")+COUNTIFS('Features'!$A$3:$A$72,"F-008",'Features'!$G$3:$G$72,"in_review")+COUNTIFS('Features'!$A$3:$A$72,"F-020",'Features'!$G$3:$G$72,"complete")+COUNTIFS('Features'!$A$3:$A$72,"F-020",'Features'!$G$3:$G$72,"in_review")+COUNTIFS('Features'!$A$3:$A$72,"F-021",'Features'!$G$3:$G$72,"complete")+COUNTIFS('Features'!$A$3:$A$72,"F-021",'Features'!$G$3:$G$72,"in_review")+COUNTIFS('Features'!$A$3:$A$72,"F-063",'Features'!$G$3:$G$72,"complete")+COUNTIFS('Features'!$A$3:$A$72,"F-063",'Features'!$G$3:$G$72,"in_review"))=5,"MET",IF((COUNTIFS('Features'!$A$3:$A$72,"F-007",'Features'!$G$3:$G$72,"complete")+COUNTIFS('Features'!$A$3:$A$72,"F-007",'Features'!$G$3:$G$72,"in_review")+COUNTIFS('Features'!$A$3:$A$72,"F-008",'Features'!$G$3:$G$72,"complete")+COUNTIFS('Features'!$A$3:$A$72,"F-008",'Features'!$G$3:$G$72,"in_review")+COUNTIFS('Features'!$A$3:$A$72,"F-020",'Features'!$G$3:$G$72,"complete")+COUNTIFS('Features'!$A$3:$A$72,"F-020",'Features'!$G$3:$G$72,"in_review")+COUNTIFS('Features'!$A$3:$A$72,"F-021",'Features'!$G$3:$G$72,"complete")+COUNTIFS('Features'!$A$3:$A$72,"F-021",'Features'!$G$3:$G$72,"in_review")+COUNTIFS('Features'!$A$3:$A$72,"F-063",'Features'!$G$3:$G$72,"complete")+COUNTIFS('Features'!$A$3:$A$72,"F-063",'Features'!$G$3:$G$72,"in_review"))=0,"OPEN — 0 of 5","PARTIAL — "&(COUNTIFS('Features'!$A$3:$A$72,"F-007",'Features'!$G$3:$G$72,"complete")+COUNTIFS('Features'!$A$3:$A$72,"F-007",'Features'!$G$3:$G$72,"in_review")+COUNTIFS('Features'!$A$3:$A$72,"F-008",'Features'!$G$3:$G$72,"complete")+COUNTIFS('Features'!$A$3:$A$72,"F-008",'Features'!$G$3:$G$72,"in_review")+COUNTIFS('Features'!$A$3:$A$72,"F-020",'Features'!$G$3:$G$72,"complete")+COUNTIFS('Features'!$A$3:$A$72,"F-020",'Features'!$G$3:$G$72,"in_review")+COUNTIFS('Features'!$A$3:$A$72,"F-021",'Features'!$G$3:$G$72,"complete")+COUNTIFS('Features'!$A$3:$A$72,"F-021",'Features'!$G$3:$G$72,"in_review")+COUNTIFS('Features'!$A$3:$A$72,"F-063",'Features'!$G$3:$G$72,"complete")+COUNTIFS('Features'!$A$3:$A$72,"F-063",'Features'!$G$3:$G$72,"in_review"))&" of 5"))) | I9: F-007 Voice of Customer extracts verbatim language in Alpha. F-020/F-021 (Beta) consume it. Alpha can prove 'we capture the language'; only Beta proves 'it shows up in your copy'.
A10: P-006 | B10: My existing image/video set is doing something — but I can't tell what's missing or off. | C10: GA | D10: No | E10: F-006,F-007,F-054,F-055 | F10: 4 | G10: =(COUNTIFS('Features'!$A$3:$A$72,"F-006",'Features'!$G$3:$G$72,"complete")+COUNTIFS('Features'!$A$3:$A$72,"F-006",'Features'!$G$3:$G$72,"in_review")+COUNTIFS('Features'!$A$3:$A$72,"F-007",'Features'!$G$3:$G$72,"complete")+COUNTIFS('Features'!$A$3:$A$72,"F-007",'Features'!$G$3:$G$72,"in_review")+COUNTIFS('Features'!$A$3:$A$72,"F-054",'Features'!$G$3:$G$72,"complete")+COUNTIFS('Features'!$A$3:$A$72,"F-054",'Features'!$G$3:$G$72,"in_review")+COUNTIFS('Features'!$A$3:$A$72,"F-055",'Features'!$G$3:$G$72,"complete")+COUNTIFS('Features'!$A$3:$A$72,"F-055",'Features'!$G$3:$G$72,"in_review")) | H10: =IF((COUNTIFS('Features'!$A$3:$A$72,"F-006",'Features'!$G$3:$G$72,"blocked")+COUNTIFS('Features'!$A$3:$A$72,"F-007",'Features'!$G$3:$G$72,"blocked")+COUNTIFS('Features'!$A$3:$A$72,"F-054",'Features'!$G$3:$G$72,"blocked")+COUNTIFS('Features'!$A$3:$A$72,"F-055",'Features'!$G$3:$G$72,"blocked"))>0,"BLOCKED — see mapped features",IF((COUNTIFS('Features'!$A$3:$A$72,"F-006",'Features'!$G$3:$G$72,"complete")+COUNTIFS('Features'!$A$3:$A$72,"F-006",'Features'!$G$3:$G$72,"in_review")+COUNTIFS('Features'!$A$3:$A$72,"F-007",'Features'!$G$3:$G$72,"complete")+COUNTIFS('Features'!$A$3:$A$72,"F-007",'Features'!$G$3:$G$72,"in_review")+COUNTIFS('Features'!$A$3:$A$72,"F-054",'Features'!$G$3:$G$72,"complete")+COUNTIFS('Features'!$A$3:$A$72,"F-054",'Features'!$G$3:$G$72,"in_review")+COUNTIFS('Features'!$A$3:$A$72,"F-055",'Features'!$G$3:$G$72,"complete")+COUNTIFS('Features'!$A$3:$A$72,"F-055",'Features'!$G$3:$G$72,"in_review"))=4,"MET",IF((COUNTIFS('Features'!$A$3:$A$72,"F-006",'Features'!$G$3:$G$72,"complete")+COUNTIFS('Features'!$A$3:$A$72,"F-006",'Features'!$G$3:$G$72,"in_review")+COUNTIFS('Features'!$A$3:$A$72,"F-007",'Features'!$G$3:$G$72,"complete")+COUNTIFS('Features'!$A$3:$A$72,"F-007",'Features'!$G$3:$G$72,"in_review")+COUNTIFS('Features'!$A$3:$A$72,"F-054",'Features'!$G$3:$G$72,"complete")+COUNTIFS('Features'!$A$3:$A$72,"F-054",'Features'!$G$3:$G$72,"in_review")+COUNTIFS('Features'!$A$3:$A$72,"F-055",'Features'!$G$3:$G$72,"complete")+COUNTIFS('Features'!$A$3:$A$72,"F-055",'Features'!$G$3:$G$72,"in_review"))=0,"OPEN — 0 of 4","PARTIAL — "&(COUNTIFS('Features'!$A$3:$A$72,"F-006",'Features'!$G$3:$G$72,"complete")+COUNTIFS('Features'!$A$3:$A$72,"F-006",'Features'!$G$3:$G$72,"in_review")+COUNTIFS('Features'!$A$3:$A$72,"F-007",'Features'!$G$3:$G$72,"complete")+COUNTIFS('Features'!$A$3:$A$72,"F-007",'Features'!$G$3:$G$72,"in_review")+COUNTIFS('Features'!$A$3:$A$72,"F-054",'Features'!$G$3:$G$72,"complete")+COUNTIFS('Features'!$A$3:$A$72,"F-054",'Features'!$G$3:$G$72,"in_review")+COUNTIFS('Features'!$A$3:$A$72,"F-055",'Features'!$G$3:$G$72,"complete")+COUNTIFS('Features'!$A$3:$A$72,"F-055",'Features'!$G$3:$G$72,"in_review"))&" of 4"))) | I10: InfinityVault's specific need (N-002). F-054 is conditional on the asset-tracking decision gate. F-006/F-007 supply the 'what should this connect to' context.
A11: P-007 | B11: I have no thinking partner who remembers my brand. | C11: Beta | D11: No | E11: F-022,F-031,F-049 | F11: 3 | G11: =(COUNTIFS('Features'!$A$3:$A$72,"F-022",'Features'!$G$3:$G$72,"complete")+COUNTIFS('Features'!$A$3:$A$72,"F-022",'Features'!$G$3:$G$72,"in_review")+COUNTIFS('Features'!$A$3:$A$72,"F-031",'Features'!$G$3:$G$72,"complete")+COUNTIFS('Features'!$A$3:$A$72,"F-031",'Features'!$G$3:$G$72,"in_review")+COUNTIFS('Features'!$A$3:$A$72,"F-049",'Features'!$G$3:$G$72,"complete")+COUNTIFS('Features'!$A$3:$A$72,"F-049",'Features'!$G$3:$G$72,"in_review")) | H11: =IF((COUNTIFS('Features'!$A$3:$A$72,"F-022",'Features'!$G$3:$G$72,"blocked")+COUNTIFS('Features'!$A$3:$A$72,"F-031",'Features'!$G$3:$G$72,"blocked")+COUNTIFS('Features'!$A$3:$A$72,"F-049",'Features'!$G$3:$G$72,"blocked"))>0,"BLOCKED — see mapped features",IF((COUNTIFS('Features'!$A$3:$A$72,"F-022",'Features'!$G$3:$G$72,"complete")+COUNTIFS('Features'!$A$3:$A$72,"F-022",'Features'!$G$3:$G$72,"in_review")+COUNTIFS('Features'!$A$3:$A$72,"F-031",'Features'!$G$3:$G$72,"complete")+COUNTIFS('Features'!$A$3:$A$72,"F-031",'Features'!$G$3:$G$72,"in_review")+COUNTIFS('Features'!$A$3:$A$72,"F-049",'Features'!$G$3:$G$72,"complete")+COUNTIFS('Features'!$A$3:$A$72,"F-049",'Features'!$G$3:$G$72,"in_review"))=3,"MET",IF((COUNTIFS('Features'!$A$3:$A$72,"F-022",'Features'!$G$3:$G$72,"complete")+COUNTIFS('Features'!$A$3:$A$72,"F-022",'Features'!$G$3:$G$72,"in_review")+COUNTIFS('Features'!$A$3:$A$72,"F-031",'Features'!$G$3:$G$72,"complete")+COUNTIFS('Features'!$A$3:$A$72,"F-031",'Features'!$G$3:$G$72,"in_review")+COUNTIFS('Features'!$A$3:$A$72,"F-049",'Features'!$G$3:$G$72,"complete")+COUNTIFS('Features'!$A$3:$A$72,"F-049",'Features'!$G$3:$G$72,"in_review"))=0,"OPEN — 0 of 3","PARTIAL — "&(COUNTIFS('Features'!$A$3:$A$72,"F-022",'Features'!$G$3:$G$72,"complete")+COUNTIFS('Features'!$A$3:$A$72,"F-022",'Features'!$G$3:$G$72,"in_review")+COUNTIFS('Features'!$A$3:$A$72,"F-031",'Features'!$G$3:$G$72,"complete")+COUNTIFS('Features'!$A$3:$A$72,"F-031",'Features'!$G$3:$G$72,"in_review")+COUNTIFS('Features'!$A$3:$A$72,"F-049",'Features'!$G$3:$G$72,"complete")+COUNTIFS('Features'!$A$3:$A$72,"F-049",'Features'!$G$3:$G$72,"in_review"))&" of 3"))) | I11: F-022 Coach mode is the answer. RAG (F-049) makes the memory queryable. F-031 (My Brands) lets the partner know which brand we're discussing.
A12: P-008 | B12: I can't cheaply test multiple positioning angles. | C12: Beta | D12: No | E12: F-042,F-053,F-055 | F12: 3 | G12: =(COUNTIFS('Features'!$A$3:$A$72,"F-042",'Features'!$G$3:$G$72,"complete")+COUNTIFS('Features'!$A$3:$A$72,"F-042",'Features'!$G$3:$G$72,"in_review")+COUNTIFS('Features'!$A$3:$A$72,"F-053",'Features'!$G$3:$G$72,"complete")+COUNTIFS('Features'!$A$3:$A$72,"F-053",'Features'!$G$3:$G$72,"in_review")+COUNTIFS('Features'!$A$3:$A$72,"F-055",'Features'!$G$3:$G$72,"complete")+COUNTIFS('Features'!$A$3:$A$72,"F-055",'Features'!$G$3:$G$72,"in_review")) | H12: =IF((COUNTIFS('Features'!$A$3:$A$72,"F-042",'Features'!$G$3:$G$72,"blocked")+COUNTIFS('Features'!$A$3:$A$72,"F-053",'Features'!$G$3:$G$72,"blocked")+COUNTIFS('Features'!$A$3:$A$72,"F-055",'Features'!$G$3:$G$72,"blocked"))>0,"BLOCKED — see mapped features",IF((COUNTIFS('Features'!$A$3:$A$72,"F-042",'Features'!$G$3:$G$72,"complete")+COUNTIFS('Features'!$A$3:$A$72,"F-042",'Features'!$G$3:$G$72,"in_review")+COUNTIFS('Features'!$A$3:$A$72,"F-053",'Features'!$G$3:$G$72,"complete")+COUNTIFS('Features'!$A$3:$A$72,"F-053",'Features'!$G$3:$G$72,"in_review")+COUNTIFS('Features'!$A$3:$A$72,"F-055",'Features'!$G$3:$G$72,"complete")+COUNTIFS('Features'!$A$3:$A$72,"F-055",'Features'!$G$3:$G$72,"in_review"))=3,"MET",IF((COUNTIFS('Features'!$A$3:$A$72,"F-042",'Features'!$G$3:$G$72,"complete")+COUNTIFS('Features'!$A$3:$A$72,"F-042",'Features'!$G$3:$G$72,"in_review")+COUNTIFS('Features'!$A$3:$A$72,"F-053",'Features'!$G$3:$G$72,"complete")+COUNTIFS('Features'!$A$3:$A$72,"F-053",'Features'!$G$3:$G$72,"in_review")+COUNTIFS('Features'!$A$3:$A$72,"F-055",'Features'!$G$3:$G$72,"complete")+COUNTIFS('Features'!$A$3:$A$72,"F-055",'Features'!$G$3:$G$72,"in_review"))=0,"OPEN — 0 of 3","PARTIAL — "&(COUNTIFS('Features'!$A$3:$A$72,"F-042",'Features'!$G$3:$G$72,"complete")+COUNTIFS('Features'!$A$3:$A$72,"F-042",'Features'!$G$3:$G$72,"in_review")+COUNTIFS('Features'!$A$3:$A$72,"F-053",'Features'!$G$3:$G$72,"complete")+COUNTIFS('Features'!$A$3:$A$72,"F-053",'Features'!$G$3:$G$72,"in_review")+COUNTIFS('Features'!$A$3:$A$72,"F-055",'Features'!$G$3:$G$72,"complete")+COUNTIFS('Features'!$A$3:$A$72,"F-055",'Features'!$G$3:$G$72,"in_review"))&" of 3"))) | I12: F-053 is the primary fulfilment. F-055 lets each angle drive its own design brief. F-042 comparison view (GA) lets the user A/B them.
A13: P-009 | B13: I can't tell when my strategy and my live assets have drifted apart. | C13: GA | D13: No | E13: F-028,F-029,F-030,F-043,F-054 | F13: 5 | G13: =(COUNTIFS('Features'!$A$3:$A$72,"F-028",'Features'!$G$3:$G$72,"complete")+COUNTIFS('Features'!$A$3:$A$72,"F-028",'Features'!$G$3:$G$72,"in_review")+COUNTIFS('Features'!$A$3:$A$72,"F-029",'Features'!$G$3:$G$72,"complete")+COUNTIFS('Features'!$A$3:$A$72,"F-029",'Features'!$G$3:$G$72,"in_review")+COUNTIFS('Features'!$A$3:$A$72,"F-030",'Features'!$G$3:$G$72,"complete")+COUNTIFS('Features'!$A$3:$A$72,"F-030",'Features'!$G$3:$G$72,"in_review")+COUNTIFS('Features'!$A$3:$A$72,"F-043",'Features'!$G$3:$G$72,"complete")+COUNTIFS('Features'!$A$3:$A$72,"F-043",'Features'!$G$3:$G$72,"in_review")+COUNTIFS('Features'!$A$3:$A$72,"F-054",'Features'!$G$3:$G$72,"complete")+COUNTIFS('Features'!$A$3:$A$72,"F-054",'Features'!$G$3:$G$72,"in_review")) | H13: =IF((COUNTIFS('Features'!$A$3:$A$72,"F-028",'Features'!$G$3:$G$72,"blocked")+COUNTIFS('Features'!$A$3:$A$72,"F-029",'Features'!$G$3:$G$72,"blocked")+COUNTIFS('Features'!$A$3:$A$72,"F-030",'Features'!$G$3:$G$72,"blocked")+COUNTIFS('Features'!$A$3:$A$72,"F-043",'Features'!$G$3:$G$72,"blocked")+COUNTIFS('Features'!$A$3:$A$72,"F-054",'Features'!$G$3:$G$72,"blocked"))>0,"BLOCKED — see mapped features",IF((COUNTIFS('Features'!$A$3:$A$72,"F-028",'Features'!$G$3:$G$72,"complete")+COUNTIFS('Features'!$A$3:$A$72,"F-028",'Features'!$G$3:$G$72,"in_review")+COUNTIFS('Features'!$A$3:$A$72,"F-029",'Features'!$G$3:$G$72,"complete")+COUNTIFS('Features'!$A$3:$A$72,"F-029",'Features'!$G$3:$G$72,"in_review")+COUNTIFS('Features'!$A$3:$A$72,"F-030",'Features'!$G$3:$G$72,"complete")+COUNTIFS('Features'!$A$3:$A$72,"F-030",'Features'!$G$3:$G$72,"in_review")+COUNTIFS('Features'!$A$3:$A$72,"F-043",'Features'!$G$3:$G$72,"complete")+COUNTIFS('Features'!$A$3:$A$72,"F-043",'Features'!$G$3:$G$72,"in_review")+COUNTIFS('Features'!$A$3:$A$72,"F-054",'Features'!$G$3:$G$72,"complete")+COUNTIFS('Features'!$A$3:$A$72,"F-054",'Features'!$G$3:$G$72,"in_review"))=5,"MET",IF((COUNTIFS('Features'!$A$3:$A$72,"F-028",'Features'!$G$3:$G$72,"complete")+COUNTIFS('Features'!$A$3:$A$72,"F-028",'Features'!$G$3:$G$72,"in_review")+COUNTIFS('Features'!$A$3:$A$72,"F-029",'Features'!$G$3:$G$72,"complete")+COUNTIFS('Features'!$A$3:$A$72,"F-029",'Features'!$G$3:$G$72,"in_review")+COUNTIFS('Features'!$A$3:$A$72,"F-030",'Features'!$G$3:$G$72,"complete")+COUNTIFS('Features'!$A$3:$A$72,"F-030",'Features'!$G$3:$G$72,"in_review")+COUNTIFS('Features'!$A$3:$A$72,"F-043",'Features'!$G$3:$G$72,"complete")+COUNTIFS('Features'!$A$3:$A$72,"F-043",'Features'!$G$3:$G$72,"in_review")+COUNTIFS('Features'!$A$3:$A$72,"F-054",'Features'!$G$3:$G$72,"complete")+COUNTIFS('Features'!$A$3:$A$72,"F-054",'Features'!$G$3:$G$72,"in_review"))=0,"OPEN — 0 of 5","PARTIAL — "&(COUNTIFS('Features'!$A$3:$A$72,"F-028",'Features'!$G$3:$G$72,"complete")+COUNTIFS('Features'!$A$3:$A$72,"F-028",'Features'!$G$3:$G$72,"in_review")+COUNTIFS('Features'!$A$3:$A$72,"F-029",'Features'!$G$3:$G$72,"complete")+COUNTIFS('Features'!$A$3:$A$72,"F-029",'Features'!$G$3:$G$72,"in_review")+COUNTIFS('Features'!$A$3:$A$72,"F-030",'Features'!$G$3:$G$72,"complete")+COUNTIFS('Features'!$A$3:$A$72,"F-030",'Features'!$G$3:$G$72,"in_review")+COUNTIFS('Features'!$A$3:$A$72,"F-043",'Features'!$G$3:$G$72,"complete")+COUNTIFS('Features'!$A$3:$A$72,"F-043",'Features'!$G$3:$G$72,"in_review")+COUNTIFS('Features'!$A$3:$A$72,"F-054",'Features'!$G$3:$G$72,"complete")+COUNTIFS('Features'!$A$3:$A$72,"F-054",'Features'!$G$3:$G$72,"in_review"))&" of 5"))) | I13: Conditional on the asset-tracking decision. F-043 field edit history adds the temporal dimension on the strategy side.
A14: P-010 | B14: Every marketing decision feels reactive. | C14: GA | D14: No | E14: F-008,F-022,F-038,F-053 | F14: 4 | G14: =(COUNTIFS('Features'!$A$3:$A$72,"F-008",'Features'!$G$3:$G$72,"complete")+COUNTIFS('Features'!$A$3:$A$72,"F-008",'Features'!$G$3:$G$72,"in_review")+COUNTIFS('Features'!$A$3:$A$72,"F-022",'Features'!$G$3:$G$72,"complete")+COUNTIFS('Features'!$A$3:$A$72,"F-022",'Features'!$G$3:$G$72,"in_review")+COUNTIFS('Features'!$A$3:$A$72,"F-038",'Features'!$G$3:$G$72,"complete")+COUNTIFS('Features'!$A$3:$A$72,"F-038",'Features'!$G$3:$G$72,"in_review")+COUNTIFS('Features'!$A$3:$A$72,"F-053",'Features'!$G$3:$G$72,"complete")+COUNTIFS('Features'!$A$3:$A$72,"F-053",'Features'!$G$3:$G$72,"in_review")) | H14: =IF((COUNTIFS('Features'!$A$3:$A$72,"F-008",'Features'!$G$3:$G$72,"blocked")+COUNTIFS('Features'!$A$3:$A$72,"F-022",'Features'!$G$3:$G$72,"blocked")+COUNTIFS('Features'!$A$3:$A$72,"F-038",'Features'!$G$3:$G$72,"blocked")+COUNTIFS('Features'!$A$3:$A$72,"F-053",'Features'!$G$3:$G$72,"blocked"))>0,"BLOCKED — see mapped features",IF((COUNTIFS('Features'!$A$3:$A$72,"F-008",'Features'!$G$3:$G$72,"complete")+COUNTIFS('Features'!$A$3:$A$72,"F-008",'Features'!$G$3:$G$72,"in_review")+COUNTIFS('Features'!$A$3:$A$72,"F-022",'Features'!$G$3:$G$72,"complete")+COUNTIFS('Features'!$A$3:$A$72,"F-022",'Features'!$G$3:$G$72,"in_review")+COUNTIFS('Features'!$A$3:$A$72,"F-038",'Features'!$G$3:$G$72,"complete")+COUNTIFS('Features'!$A$3:$A$72,"F-038",'Features'!$G$3:$G$72,"in_review")+COUNTIFS('Features'!$A$3:$A$72,"F-053",'Features'!$G$3:$G$72,"complete")+COUNTIFS('Features'!$A$3:$A$72,"F-053",'Features'!$G$3:$G$72,"in_review"))=4,"MET",IF((COUNTIFS('Features'!$A$3:$A$72,"F-008",'Features'!$G$3:$G$72,"complete")+COUNTIFS('Features'!$A$3:$A$72,"F-008",'Features'!$G$3:$G$72,"in_review")+COUNTIFS('Features'!$A$3:$A$72,"F-022",'Features'!$G$3:$G$72,"complete")+COUNTIFS('Features'!$A$3:$A$72,"F-022",'Features'!$G$3:$G$72,"in_review")+COUNTIFS('Features'!$A$3:$A$72,"F-038",'Features'!$G$3:$G$72,"complete")+COUNTIFS('Features'!$A$3:$A$72,"F-038",'Features'!$G$3:$G$72,"in_review")+COUNTIFS('Features'!$A$3:$A$72,"F-053",'Features'!$G$3:$G$72,"complete")+COUNTIFS('Features'!$A$3:$A$72,"F-053",'Features'!$G$3:$G$72,"in_review"))=0,"OPEN — 0 of 4","PARTIAL — "&(COUNTIFS('Features'!$A$3:$A$72,"F-008",'Features'!$G$3:$G$72,"complete")+COUNTIFS('Features'!$A$3:$A$72,"F-008",'Features'!$G$3:$G$72,"in_review")+COUNTIFS('Features'!$A$3:$A$72,"F-022",'Features'!$G$3:$G$72,"complete")+COUNTIFS('Features'!$A$3:$A$72,"F-022",'Features'!$G$3:$G$72,"in_review")+COUNTIFS('Features'!$A$3:$A$72,"F-038",'Features'!$G$3:$G$72,"complete")+COUNTIFS('Features'!$A$3:$A$72,"F-038",'Features'!$G$3:$G$72,"in_review")+COUNTIFS('Features'!$A$3:$A$72,"F-053",'Features'!$G$3:$G$72,"complete")+COUNTIFS('Features'!$A$3:$A$72,"F-053",'Features'!$G$3:$G$72,"in_review"))&" of 4"))) | I14: Forensic Canvas as North Star (F-008), Coach for ongoing decisions (F-022), performance metrics (F-038) close the loop. F-053 lets decisions live at the angle level.
A15: P-011 | B15: I don't know where my brand is failing. | C15: Alpha | D15: Yes | E15: F-057,F-059,F-027 | F15: 3 | G15: =(COUNTIFS('Features'!$A$3:$A$72,"F-057",'Features'!$G$3:$G$72,"complete")+COUNTIFS('Features'!$A$3:$A$72,"F-057",'Features'!$G$3:$G$72,"in_review")+COUNTIFS('Features'!$A$3:$A$72,"F-059",'Features'!$G$3:$G$72,"complete")+COUNTIFS('Features'!$A$3:$A$72,"F-059",'Features'!$G$3:$G$72,"in_review")+COUNTIFS('Features'!$A$3:$A$72,"F-027",'Features'!$G$3:$G$72,"complete")+COUNTIFS('Features'!$A$3:$A$72,"F-027",'Features'!$G$3:$G$72,"in_review")) | H15: =IF((COUNTIFS('Features'!$A$3:$A$72,"F-057",'Features'!$G$3:$G$72,"blocked")+COUNTIFS('Features'!$A$3:$A$72,"F-059",'Features'!$G$3:$G$72,"blocked")+COUNTIFS('Features'!$A$3:$A$72,"F-027",'Features'!$G$3:$G$72,"blocked"))>0,"BLOCKED — see mapped features",IF((COUNTIFS('Features'!$A$3:$A$72,"F-057",'Features'!$G$3:$G$72,"complete")+COUNTIFS('Features'!$A$3:$A$72,"F-057",'Features'!$G$3:$G$72,"in_review")+COUNTIFS('Features'!$A$3:$A$72,"F-059",'Features'!$G$3:$G$72,"complete")+COUNTIFS('Features'!$A$3:$A$72,"F-059",'Features'!$G$3:$G$72,"in_review")+COUNTIFS('Features'!$A$3:$A$72,"F-027",'Features'!$G$3:$G$72,"complete")+COUNTIFS('Features'!$A$3:$A$72,"F-027",'Features'!$G$3:$G$72,"in_review"))=3,"MET",IF((COUNTIFS('Features'!$A$3:$A$72,"F-057",'Features'!$G$3:$G$72,"complete")+COUNTIFS('Features'!$A$3:$A$72,"F-057",'Features'!$G$3:$G$72,"in_review")+COUNTIFS('Features'!$A$3:$A$72,"F-059",'Features'!$G$3:$G$72,"complete")+COUNTIFS('Features'!$A$3:$A$72,"F-059",'Features'!$G$3:$G$72,"in_review")+COUNTIFS('Features'!$A$3:$A$72,"F-027",'Features'!$G$3:$G$72,"complete")+COUNTIFS('Features'!$A$3:$A$72,"F-027",'Features'!$G$3:$G$72,"in_review"))=0,"OPEN — 0 of 3","PARTIAL — "&(COUNTIFS('Features'!$A$3:$A$72,"F-057",'Features'!$G$3:$G$72,"complete")+COUNTIFS('Features'!$A$3:$A$72,"F-057",'Features'!$G$3:$G$72,"in_review")+COUNTIFS('Features'!$A$3:$A$72,"F-059",'Features'!$G$3:$G$72,"complete")+COUNTIFS('Features'!$A$3:$A$72,"F-059",'Features'!$G$3:$G$72,"in_review")+COUNTIFS('Features'!$A$3:$A$72,"F-027",'Features'!$G$3:$G$72,"complete")+COUNTIFS('Features'!$A$3:$A$72,"F-027",'Features'!$G$3:$G$72,"in_review"))&" of 3"))) | I15: GEN3 (2026-05-25): Trevor's problem #3/#9 — the Trust Gap™ Score (F-057) names the gap (insight / positioning / empathy / authenticity) and the bridge (F-059) turns it into momentum. MVP-critical: this is the hook, validate FIRST [Analysis 2026-05-17]. Free tier.
A16: P-012 | B16: Brand strategy expertise is inaccessible at my price point. | C16: Beta | D16: No | E16: F-019,F-064 | F16: 2 | G16: =(COUNTIFS('Features'!$A$3:$A$72,"F-019",'Features'!$G$3:$G$72,"complete")+COUNTIFS('Features'!$A$3:$A$72,"F-019",'Features'!$G$3:$G$72,"in_review")+COUNTIFS('Features'!$A$3:$A$72,"F-064",'Features'!$G$3:$G$72,"complete")+COUNTIFS('Features'!$A$3:$A$72,"F-064",'Features'!$G$3:$G$72,"in_review")) | H16: =IF((COUNTIFS('Features'!$A$3:$A$72,"F-019",'Features'!$G$3:$G$72,"blocked")+COUNTIFS('Features'!$A$3:$A$72,"F-064",'Features'!$G$3:$G$72,"blocked"))>0,"BLOCKED — see mapped features",IF((COUNTIFS('Features'!$A$3:$A$72,"F-019",'Features'!$G$3:$G$72,"complete")+COUNTIFS('Features'!$A$3:$A$72,"F-019",'Features'!$G$3:$G$72,"in_review")+COUNTIFS('Features'!$A$3:$A$72,"F-064",'Features'!$G$3:$G$72,"complete")+COUNTIFS('Features'!$A$3:$A$72,"F-064",'Features'!$G$3:$G$72,"in_review"))=2,"MET",IF((COUNTIFS('Features'!$A$3:$A$72,"F-019",'Features'!$G$3:$G$72,"complete")+COUNTIFS('Features'!$A$3:$A$72,"F-019",'Features'!$G$3:$G$72,"in_review")+COUNTIFS('Features'!$A$3:$A$72,"F-064",'Features'!$G$3:$G$72,"complete")+COUNTIFS('Features'!$A$3:$A$72,"F-064",'Features'!$G$3:$G$72,"in_review"))=0,"OPEN — 0 of 2","PARTIAL — "&(COUNTIFS('Features'!$A$3:$A$72,"F-019",'Features'!$G$3:$G$72,"complete")+COUNTIFS('Features'!$A$3:$A$72,"F-019",'Features'!$G$3:$G$72,"in_review")+COUNTIFS('Features'!$A$3:$A$72,"F-064",'Features'!$G$3:$G$72,"complete")+COUNTIFS('Features'!$A$3:$A$72,"F-064",'Features'!$G$3:$G$72,"in_review"))&" of 2"))) | I16: GEN3 (2026-05-25): Trevor's problem #7 — a brand strategist costs £3k–£15k; the freemium app (F-019) delivers structured brand thinking at £29/mo, with locked-but-visible fields (F-064) enticing upgrade. Paid tier.

Sheet Features
A1: Features — implementation status by launch phase
A2: feature_id | B2: feature_name | C2: area | D2: description | E2: phase_required | F2: priority | G2: status | H2: percent_complete | I2: blocker | J2: owner | K2: depends_on | L2: problems_addressed | M2: effort_estimate_hours | N2: actual_hours | O2: notes | P2: last_updated
A3: F-001 | B3: Layer 1 conversation engine | C3: conversation | D3: 10-question Layer 1 flow with Trevor-voice fallback responses and real-time canvas-sidebar updates. | E3: Alpha | F3: P0 | G3: in_progress | H3: 35 | J3: Matthew | K3: F-018 | L3: P-002 | M3: 40 | N3: 0 | O3: AUDIT 2026-05-16: Trevor persona prompt + free-form Claude streaming exist; the *10-question script* and per-question off-topic fallbacks DO NOT (F-001.1/F-001.2). Streaming + persistence are solid. Mobile keyboard handling minimal. | P3: 46167
A4: F-002 | B4: Canvas sidebar real-time population | C4: canvas | D4: Canvas sidebar updates as Layer 1 conversation progresses, showing extracted fields with confidence indicators. | E4: Alpha | F4: P0 | G4: in_progress | H4: 65 | J4: Matthew | K4: F-001,F-012 | M4: 20 | N4: 0 | O4: AUDIT 2026-05-16: Field-extraction → sidebar pipeline is mature (F-002.1, 80%). Quality badges render BUT use value heuristics (fieldQualityScore) not extractor confidence — acceptance criterion not literally met (F-002.2 reduced from 100→75). Mobile sheet works but state not persisted (F-002.3). | P4: 46167
A5: F-003 | B5: Draft Canvas synthesis | C5: canvas | D5: Synthesise Layer 1 inputs into a coherent Draft Canvas with DRAFT badge and clear Forensic upgrade prompt. | E5: Alpha | F5: P0 | G5: in_progress | H5: 14 | J5: Matthew | K5: F-001,F-018 | L5: P-003 | M5: 24 | N5: 0 | O5: AUDIT 2026-05-16: Tier distinction is conceptual only — zero structural code hits for 'DRAFT'/'tier'. Synthesis with Trevor voice exists (generate-brand-strategy-section + voice.ts) but generates the full doc, not a Draft subset. DRAFT badge and Forensic upgrade CTA both 0%. | P5: 46167
A6: F-004 | B6: Avatar Builder — Psychographic Profile | C6: avatar_builder | D6: Section 1 of the four-section Avatar Builder. Captures values, identity, worldview. | E6: Alpha | F6: P0 | G6: in_progress | H6: 62 | J6: Matthew | K6: F-003,F-009 | L6: P-001,P-002 | M6: 32 | N6: 0 | O6: AUDIT 2026-05-16: V2 chapter UI delivers progressive disclosure + persistence well, but field schema flattens Gen 3 psychographic dimensions into coarse textareas (F-004.1 60%). 3 of 4 AI modes present; FieldChatButton missing from V2 (F-004.3 35%). Completion gate logic exists but button not mounted in render tree (F-004.5 55%). RECONCILE (2026-05-25): maps into the new 5-stage conversational flow ending in The Signature (F-060); guided dialogue, not a 4-section form [F 144128256 @04:26]. 5-stage structure pending Trevor/Matthew sign-off. | P6: 46167
A7: F-005 | B7: Avatar Builder — Buying Behaviour | C7: avatar_builder | D7: Section 2. Captures purchase triggers, objections, decision criteria, channels. | E7: Alpha | F7: P0 | G7: in_progress | H7: 55 | J7: Matthew | K7: F-004 | L7: P-001,P-002 | M7: 32 | N7: 0 | O7: AUDIT 2026-05-16: V2 chapter map has no dedicated 'Buying Behaviour' chapter — closest is BUYER_INTENT which is conceptually different. V1 AvatarBuilder has the right tab. Data shape exists; UI split V1↔V2. RECONCILE (2026-05-25): maps into the new 5-stage conversational flow ending in The Signature (F-060); guided dialogue, not a 4-section form [F 144128256 @04:26]. 5-stage structure pending Trevor/Matthew sign-off. | P7: 46167
A8: F-006 | B8: Avatar Builder — Emotional Journey Mapping | C8: avatar_builder | D8: Section 3. Pre/during/post purchase emotional states; The Decision Trigger™ originates here (captured standalone in F-058). | E8: Alpha | F8: P0 | G8: in_progress | H8: 43 | J8: Matthew | K8: F-005 | L8: P-001,P-002,P-006 | M8: 36 | N8: 0 | O8: AUDIT 2026-05-16: Emotional fields exist (EMOTIONAL_CONNECTION + CUSTOMER_EXPERIENCE chapters) but Gen 3 Emotional Journey framing absent; Trigger Moment field with elevated visual treatment (F-006.2) is the most prominent miss — zero hits in codebase. RECONCILE (2026-05-25): maps into the new 5-stage conversational flow ending in The Signature (F-060); guided dialogue, not a 4-section form [F 144128256 @04:26]. 5-stage structure pending Trevor/Matthew sign-off. | P8: 46167
A9: F-007 | B9: Avatar Builder — Voice of Customer | C9: avatar_builder | D9: Section 4. Paste-in reviews and testimonials; extract verbatim language for copy hooks. | E9: Alpha | F9: P0 | G9: in_progress | H9: 30 | J9: Matthew | K9: F-006 | L9: P-001,P-002,P-005,P-006 | M9: 40 | N9: 0 | O9: AUDIT 2026-05-16: Review intake is URL/ASIN-driven via ReviewAnalyzerModal (scrape model), not Gen 3 paste-raw-reviews model. voice-of-customer-analysis edge function DOES NOT EXIST. V1 analysis is fully mocked. Use/discard phrase cards (F-007.3) ~10%. RECONCILE (2026-05-25): maps into the new 5-stage conversational flow ending in The Signature (F-060); guided dialogue, not a 4-section form [F 144128256 @04:26]. 5-stage structure pending Trevor/Matthew sign-off. | P9: 46167
A10: F-008 | B10: Forensic Canvas synthesis | C10: canvas | D10: 28+ field canvas synthesised from Avatar Builder, auto-populating from Avatar data partially in real time; strategy doc generable at any point (no forced step-gating). The Decision Trigger™ displayed prominently. | E10: Alpha | F10: P0 | G10: in_progress | H10: 39 | J10: Matthew | K10: F-004,F-005,F-006,F-007 | L10: P-001,P-003,P-004,P-005,P-010 | M10: 40 | N10: 0 | O10: AUDIT 2026-05-16: 35-field schema exists (exceeds 28+) and Markdown export pipeline is mature, but Forensic *tier* differentiation does NOT exist — single unified synthesis path. Trigger Moment 'Strategic Entry Point' callout (F-008.3) and Draft↔Forensic toggle (F-008.4) both 0%. Rollup dropped from 80→39%: the doc ships, but the criteria asking for tier-specific behaviour are unmet. GEN3 (2026-05-25): canvas auto-populates from Avatar data (partially real-time); no forced step-gating; 'Trigger Moment' renamed The Decision Trigger™ (also captured standalone in F-058) [F 144128256 @27:00,@31:00]. | P10: 46167
A11: F-009 | B11: AI Assistance system | C11: avatar_builder | D11: Four modes — Think About This, Real-World Examples, Get AI Suggestions, Get AI Auto-Populate — available per field. | E11: Alpha | F11: P0 | G11: in_progress | H11: 19 | J11: Matthew | K11: F-018 | L11: P-001,P-002 | M11: 48 | N11: 0 | O11: AUDIT 2026-05-16: Only ONE AI mode is independently invocable — a single 'Generate with AI' button per field (AIButton.tsx). 'Think About This' and 'Real-World Examples' modes don't exist; 'Auto-Populate' is delivered implicitly via chat extraction + ghost text. No 4-mode selector UI. Rollup dropped from 30→19%. GEN3 (2026-05-25): MVP ships static example text for avatar/Before-State prompts; AI-suggestion path deferred and paid-tier when built [F 144128256 @11:42-12:52]. | P11: 46167
A12: F-010 | B12: Progressive disclosure UI | C12: design_system | D12: Avatar Builder fields reveal progressively to avoid form fatigue; mobile-first. | E12: Alpha | F12: P0 | G12: not_started | H12: 2 | J12: Matthew | M12: 24 | N12: 0 | O12: AUDIT 2026-05-16: shadcn Accordion used informally for chapter disclosure; no documented disclosure pattern, no mobile-first audit committed. Rollup dropped from 25→3%. | P12: 46167
A13: F-011 | B13: Manual edit lock | C13: avatar_builder | D13: Fields manually edited by the user are flagged and never silently overwritten by AI suggestions. | E13: Alpha | F13: P0 | G13: in_progress | H13: 57 | J13: Matthew | M13: 12 | N13: 0 | O13: AUDIT 2026-05-16: field_source ('ai'|'manual') exists and survives reload BUT is not the same as a 'manuallyEdited' boolean — system pairs it with separate is_locked user-toggle. AI overwrite guard works only for *explicitly locked* fields (F-011.2 65%), not for manually edited unlocked ones. F-011.1 reduced from 100→70% in_review. | P13: 46167
A14: F-012 | B14: Field extraction pipeline with confidence scoring | C14: infrastructure | D14: Conversation inputs → structured field extraction with per-field confidence score. Drives the quality badges. | E14: Alpha | F14: P0 | G14: in_progress | H14: 45 | J14: Matthew | L14: P-001 | M14: 32 | N14: 0 | O14: AUDIT 2026-05-16: Edge function returns confidence scores (F-012.1 85%), but no confidence→badge mapping is implemented (F-012.2 was 100% wrongly — now 50%). Two unrelated badge systems coexist (heuristic on sidebar, percentage on chat). | P14: 46167
A15: F-013 | B15: Feedback Moment 1 — Entry signal modal | C15: feedback_loop | D15: Modal after Draft Canvas asks whether the conversation revealed new territory; routes to feedback sheet. | E15: Alpha | F15: P0 | G15: not_started | H15: 0 | J15: Matthew | K15: F-003,F-017 | M15: 12 | N15: 0 | O15: AUDIT 2026-05-16: Nothing exists. BrandCanvas page has no first-view detection, no modal, no 'entry signal' question copy, no moment-tagged write path. Greenfield build needed. | P15: 46167
A16: F-014 | B16: Feedback Moment 2 — Use intent inline panel | C16: feedback_loop | D16: Inline panel after Forensic Canvas asks what the user intends to do with it (and surfaces asset-update demand signal). | E16: Alpha | F16: P0 | G16: not_started | H16: 0 | J16: Matthew | K16: F-008,F-017 | M16: 12 | N16: 0 | O16: AUDIT 2026-05-16: Nothing exists. No inline panel, no 'use intent' multi-select, no 'update existing assets' option (which drives the asset-tracking gate), no moment-2 write path. Greenfield build needed. | P16: 46167
A17: F-015 | B17: Feedback Moment 3 — 14-day async email | C17: feedback_loop | D17: Day-14 email asks what the user has actually done with the canvas and what's missing. | E17: Alpha | F17: P0 | G17: not_started | H17: 0 | J17: Matthew | K17: F-017 | M17: 8 | N17: 0 | O17: AUDIT 2026-05-16: Nothing exists. No scheduled-send infrastructure (pg_cron not enabled, no day-offset queue), no 14-day email template, no inbound reply parsing. Resend exists only for synchronous send-framework-email (different feature). Greenfield build needed. | P17: 46167
A18: F-016 | B18: Feedback response sheet integration | C18: infrastructure | D18: All three feedback moments write to a single sheet (Google Sheets or Supabase view) Matthew can monitor daily. | E18: Alpha | F18: P0 | G18: not_started | H18: 0 | J18: Matthew | M18: 8 | N18: 0 | O18: AUDIT 2026-05-16: Existing beta_feedback table is wide-form (overall_rating/liked_most/improvements/issues) — wrong shape for moment-tagged events. Need new feedback_events table with (moment, user_id, timestamp, payload JSONB). Existing BetaFeedback infrastructure will NOT compose — treat as separate older system; build moment infra fresh. | P18: 46167
A19: F-017 | B19: Error monitoring | C19: infrastructure | D19: Sentry (or equivalent) capturing client + edge function errors. Daily review during alpha. | E19: Alpha | F19: P0 | G19: not_started | H19: 0 | J19: Matthew | M19: 6 | N19: 0 | O19: AUDIT 2026-05-16: Nothing exists. No Sentry/Rollbar/Bugsnag/LogRocket/Datadog in package.json. ErrorBoundary.tsx only console.errors with a commented placeholder. No source-map upload, no CI workflows directory. Greenfield install. | P19: 46167
A20: F-018 | B20: Tester onboarding flow | C20: accounts | D20: One-page Loom + in-app welcome that frames alpha state and the three feedback moments. | E20: Alpha | F20: P0 | G20: in_progress | H20: 13 | J20: Matthew | M20: 8 | N20: 0 | O20: AUDIT 2026-05-16: BetaWelcome page exists at /beta but is a self-serve registration form gated by localStorage — not auto-shown on first login, doesn't name Trevor or framework, not dismissable. StartHere has a Vimeo intro (not Loom). No invitation template, no 'first 10'/'7-day'/'30-min debrief' language. Resend not configured for invitations. | P20: 46167
A21: F-019 | B21: Pay gate (freemium) | C21: pay_gate | D21: Freemium model. Free = core tools + The Signature + limited AI; paid (£29/mo; one-off £67 notional/TBD) unlocks AI-heavy features (Review Lab analysis, unlimited prompts/iterations). Stripe + post-payment action menu. | E21: Beta | F21: P0 | G21: not_started | H21: 0 | J21: Matthew | K21: F-008 | L21: P-012 | M21: 40 | N21: 0 | O21: Central conversion test of beta. Pay-gate previews must use real canvas data. GEN3 (2026-05-25): reframed from two pricing tiers to freemium; canvas fields locked-but-visible for non-subscribers (F-064) [F 144128256 @32:26-34:29]. | P21: 46167
A22: F-020 | B22: Create mode — Amazon listing copy | C22: create_mode | D22: Generate Amazon listing copy from Forensic Canvas using Trevor-voice prompts. | E22: Beta | F22: P0 | G22: not_started | H22: 0 | J22: Matthew | K22: F-008,F-019 | L22: P-004,P-005 | M22: 32 | N22: 0 | O22: First Create-mode output. Anchors the pay-gate preview. | P22: 46167
A23: F-021 | B23: Create mode — Brand Voice Guide | C23: create_mode | D23: Generate Brand Voice Guide document from Forensic Canvas. | E23: Beta | F23: P0 | G23: not_started | H23: 0 | J23: Matthew | K23: F-008,F-019 | L23: P-004,P-005 | M23: 24 | N23: 0 | P23: 46167
A24: F-022 | B24: Coach mode v1 | C24: coach_mode | D24: Open conversation with full canvas context and document upload support. | E24: Beta | F24: P0 | G24: not_started | H24: 0 | J24: Matthew | K24: F-008 | L24: P-001,P-007,P-010 | M24: 56 | N24: 0 | O24: Required to deliver the £29/mo subscription value prop per Trevor's spec. GEN3 (2026-05-25): Coach auto-briefed on Diagnostic + Avatar data — no manual re-paste (fixes Gen-1 CX) [F 144128256 @34:29]. | P24: 46167
